Workbook

Sheet score
A1: order_id | B1: customer_id | C1: product | D1: 申请时间 | E1: 尾号 | F1: 渠道 | G1: 渠道组 | H1: label | I1: sdc1_score | J1: PHLSY_3002_score_ice | K1: PHLSY_3002_score_ice2 | L1: PHLSY_3002_score_base001 | M1: PHLSY_3002_score_base002 | N1: PHLSY_3001_PHLSY_3001 | O1: PHLSY2016_PHLSY2016 | P1: PHLSY2017_PHLSY2017 | Q1: PHLSY2018_PHLSY2018 | R1: PHLSY_2024_PHLSY_2024 | S1: PHLSY_2025_score_v1 | T1: SF_MODEL_SCORE_ice_repayment_ability_score_v1 | U1: SF_MODEL_SCORE_ice_repayment_ability_score_v2 | V1: SF_MODEL_SCORE_ice_repayment_ability_score_v3 | W1: SF_MODEL_SCORE_ice_repayment_ability_score_v4 | X1: SF_MODEL_SCORE_ice_repayment_ability_score_v5 | Y1: SF_MODEL_SCORE_ice_repayment_ability_score_v6 | Z1: SF_MODEL_SCORE_ice_repayment_ability_score_v7 | AA1: SF_MODEL_SCORE_ice_repayment_ability_score_v8 | AB1: SF_MODEL_SCORE_ice_repayment_ability_score_v9 | AC1: SF_MODEL_SCORE_PHLSY2016_score | AD1: SF_MODEL_SCORE_PHLSY2024_score | AE1: SF_MODEL_SCORE_PHLSY3001_score | AF1: SF_MODEL_SCORE_PHLSY3002_score_ice | AG1: SF_MODEL_SCORE_PHLSY3002_score_ice2 | AH1: SF_MODEL_SCORE_PHLSY3002_score_base001 | AI1: SF_MODEL_SCORE_PHLSY3002_score_base002 | AJ1: SF_MODEL_SCORE_ice_repayment_ability_score_v10 | AK1: SF_MODEL_SCORE_dyna_sdc1_score | AL1: SF_MODEL_SCORE_dyna_sdc1_amlba_score
A2: 16 | B2: 22 | C2: oceanidfund | D2: 46106.863 | E2: 2 | F2: Apple Search Ads | G2: ASA | H2: 1 | I2: =VLOOKUP(A2,[1]模型分!$A:$T,20,FALSE) -> 696 | J2: 0.52284734 | K2: 0.47074762 | L2: 0.84721627 | M2: 0.67642279 | N2: 0.526972 | O2: 0.450867 | P2: 0.733568 | Q2: 0.597206 | R2: 0.50251 | S2: 501.96575 | T2: 432 | U2: 670 | V2: 689 | W2: 473 | X2: 444 | Y2: 517 | Z2: 416 | AA2: 465 | AB2: 501 | AC2: 0.450867 | AD2: 0.50251 | AE2: 0.526972 | AF2: 0.52284734 | AG2: 0.47074762 | AH2: 0.84721627 | AI2: 0.67642279
A3: 20 | B3: 30 | C3: oceanidfund | D3: 46107.639 | E3: 0 | F3: Apple Search Ads | G3: ASA | H3: 1 | I3: =VLOOKUP(A3,[1]模型分!$A:$T,20,FALSE) -> 769 | J3: 0.65921541 | K3: 0.68357923 | L3: 0.73756026 | M3: 0.67514977 | N3: 0.650145 | O3: 0.491587 | P3: 0.73913 | Q3: 0.500039 | R3: 0.546918 | S3: 524.08922 | T3: 446 | U3: 474 | V3: 542 | W3: 519 | X3: 496 | Y3: 434 | Z3: 442 | AA3: 523 | AB3: 503 | AC3: 0.491587 | AD3: 0.546918 | AE3: 0.650145 | AF3: 0.65921541 | AG3: 0.68357923 | AH3: 0.73756026 | AI3: 0.67514977
A4: 23 | B4: 35 | C4: oceanidfund | D4: 46107.847 | E4: 5 | F4: Apple Search Ads | G4: ASA | H4: 0 | I4: =VLOOKUP(A4,[1]模型分!$A:$T,20,FALSE) -> 699 | J4: 0.52284734 | K4: 0.47074762 | L4: 0.60294086 | M4: 0.67514977 | N4: 0.528217 | O4: 0.411008 | P4: 0.630034 | Q4: 0.396925 | R4: 0.330383 | S4: 582.24324 | T4: 432 | U4: 670 | V4: 686 | W4: 473 | X4: 444 | Y4: 519 | Z4: 416 | AA4: 465 | AB4: 501 | AC4: 0.411008 | AD4: 0.330383 | AE4: 0.528217 | AF4: 0.52284734 | AG4: 0.47074762 | AH4: 0.60294086 | AI4: 0.67514977
A5: 32 | B5: 48 | C5: topbetpeso | D5: 46061.483 | E5: 8 | F5: Apple Search Ads | G5: ASA | H5: 0 | I5: =VLOOKUP(A5,[1]模型分!$A:$T,20,FALSE) -> 582 | J5: 0.79416579 | K5: 0.70559745 | L5: 0.88707747 | M5: 0.67656439 | N5: 0.708581 | O5: 0.373235 | P5: 0.708287 | Q5: 0.454796 | R5: 0.5159 | S5: 486.14419
A6: 35 | B6: 51 | C6: oceanidfund | D6: 46109.191 | E6: 1 | F6: Apple Search Ads | G6: ASA | H6: 1 | I6: =VLOOKUP(A6,[1]模型分!$A:$T,20,FALSE) -> 694 | J6: 0.63547248 | K6: 0.78168651 | L6: 0.82943513 | M6: 0.70035266 | N6: 0.644336 | O6: 0.545183 | P6: 0.716341 | Q6: 0.480057 | R6: 0.562771 | S6: 537.41328 | T6: 432 | U6: 553 | V6: 428 | W6: 465 | X6: 365 | Y6: 470 | Z6: 405 | AA6: 432 | AB6: 389 | AC6: 0.545183 | AD6: 0.562771 | AE6: 0.644336 | AF6: 0.63547248 | AG6: 0.78168651 | AH6: 0.82943513 | AI6: 0.70035266
A7: 41 | B7: 63 | C7: oceanidfund | D7: 46109.482 | E7: 3 | F7: Apple Search Ads | G7: ASA | H7: 0 | I7: =VLOOKUP(A7,[1]模型分!$A:$T,20,FALSE) -> 726 | J7: 0.18668092 | K7: 0.24990399 | L7: 0.85276663 | M7: 0.67656439 | N7: 0.54217 | O7: 0.549345 | P7: 0.713099 | Q7: 0.572406 | R7: 0.554041 | S7: 533.75024 | T7: 694 | U7: 591 | V7: 643 | W7: 640 | X7: 482 | Y7: 539 | Z7: 588 | AA7: 716 | AB7: 732 | AC7: 0.549345 | AD7: 0.554041 | AE7: 0.54217 | AF7: 0.18668092 | AG7: 0.24990399 | AH7: 0.85276663 | AI7: 0.67656439
A8: 43 | B8: 63 | C8: topbetpeso | D8: 46061.939 | E8: 3 | F8: Apple Search Ads | G8: ASA | H8: 1 | I8: =VLOOKUP(A8,[1]模型分!$A:$T,20,FALSE) -> 413 | J8: 0.66623764 | K8: 0.58768148 | L8: 0.8026366 | M8: 0.67642279 | N8: 0.658945 | O8: 0.441296 | P8: 0.715776 | Q8: 0.495035 | R8: 0.531049 | S8: 488.54679
A9: 45 | B9: 68 | C9: oceanidfund | D9: 46109.55 | E9: 8 | F9: Apple Search Ads | G9: ASA | H9: 1 | I9: =VLOOKUP(A9,[1]模型分!$A:$T,20,FALSE) -> 707 | J9: 0.55176611 | K9: 0.33802714 | L9: 0.83455661 | M9: 0.67537235 | N9: 0.654384 | O9: 0.419812 | P9: 0.59177 | Q9: 0.398912 | R9: 0.557472 | S9: 542.54166 | T9: 634 | U9: 503 | V9: 542 | W9: 583 | X9: 522 | Y9: 523 | Z9: 578 | AA9: 627 | AB9: 629 | AC9: 0.419812 | AD9: 0.557472 | AE9: 0.654384 | AF9: 0.55176611 | AG9: 0.33802714 | AH9: 0.83455661 | AI9: 0.67537235
A10: 49 | B10: 74 | C10: oceanidfund | D10: 46109.602 | E10: 4 | F10: Apple Search Ads | G10: ASA | H10: 1 | I10: =VLOOKUP(A10,[1]模型分!$A:$T,20,FALSE) -> 0 | J10: 0.80241463 | K10: 0.88152338 | L10: 0.81691776 | M10: 0.84134549 | N10: 0.552371 | O10: 0.825475 | P10: 0.690701 | Q10: 0.408728 | R10: 0.333727 | S10: 566.77546 | T10: 441 | U10: 479 | V10: 428 | W10: 464 | X10: 380 | Y10: 418 | Z10: 413 | AA10: 436 | AB10: 401 | AC10: 0.825475 | AD10: 0.333727 | AE10: 0.552371 | AF10: 0.80241463 | AG10: 0.88152338 | AH10: 0.81691776 | AI10: 0.84134549
A11: 54 | B11: 70 | C11: topbetpeso | D11: 46062.364 | E11: 0 | F11: Apple Search Ads | G11: ASA | H11: 0 | I11: =VLOOKUP(A11,[1]模型分!$A:$T,20,FALSE) -> 0 | J11: 0.37227994 | K11: 0.52903322 | L11: 0.76007063 | M11: 0.67642279 | N11: 0.522913 | O11: 0.546766 | P11: 0.729614 | Q11: 0.466184 | R11: 0.405534 | S11: 581.62384
A12: 56 | B12: 84 | C12: oceanidfund | D12: 46109.833 | E12: 4 | F12: Apple Search Ads | G12: ASA | H12: 1 | I12: =VLOOKUP(A12,[1]模型分!$A:$T,20,FALSE) -> 643 | J12: 0.67804276 | K12: 0.52895809 | L12: 0.79130846 | M12: 0.67642279 | N12: 0.421482 | O12: 0.401659 | P12: 0.702751 | Q12: 0.453736 | R12: 0.506222 | S12: 545.05858 | T12: 498 | U12: 646 | V12: 646 | W12: 549 | X12: 538 | Y12: 614 | Z12: 451 | AA12: 560 | AB12: 570 | AC12: 0.401659 | AD12: 0.506222 | AE12: 0.421482 | AF12: 0.67804276 | AG12: 0.52895809 | AH12: 0.79130846 | AI12: 0.67642279
A13: 61 | B13: 94 | C13: oceanidfund | D13: 46109.919 | E13: 4 | F13: Apple Search Ads | G13: ASA | H13: 1 | I13: =VLOOKUP(A13,[1]模型分!$A:$T,20,FALSE) -> 0 | J13: 0.75260189 | K13: 0.82257358 | L13: 0.83096885 | M13: 0.67514977 | N13: 0.676578 | O13: 0.505922 | P13: 0.729412 | Q13: 0.544457 | R13: 0.478032 | S13: 545.88638 | T13: 431 | U13: 464 | V13: 529 | W13: 503 | X13: 521 | Y13: 437 | Z13: 410 | AA13: 502 | AB13: 521 | AC13: 0.505922 | AD13: 0.478032 | AE13: 0.676578 | AF13: 0.75260189 | AG13: 0.82257358 | AH13: 0.83096885 | AI13: 0.67514977
A14: 62 | B14: 92 | C14: topbetpeso | D14: 46062.644 | E14: 2 | F14: Apple Search Ads | G14: ASA | H14: 1 | I14: =VLOOKUP(A14,[1]模型分!$A:$T,20,FALSE) -> 707 | J14: 0.553777 | K14: 0.42270677 | L14: 0.89997203 | M14: 0.67656439 | N14: 0.58653 | O14: 0.44639 | P14: 0.609435 | Q14: 0.407147 | R14: 0.43086 | S14: 500.75757
A15: 71 | B15: 107 | C15: oceanidfund | D15: 46110.158 | E15: 7 | F15: Apple Search Ads | G15: ASA | H15: 1 | I15: =VLOOKUP(A15,[1]模型分!$A:$T,20,FALSE) -> 0 | J15: 0.63303754 | K15: 0.67060419 | L15: 0.83081002 | M15: 0.67656439 | N15: 0.602978 | O15: 0.549574 | P15: 0.753642 | Q15: 0.462345 | R15: 0.476884 | S15: 536.32435 | T15: 452 | U15: 641 | V15: 615 | W15: 529 | X15: 498 | Y15: 542 | Z15: 424 | AA15: 483 | AB15: 498 | AC15: 0.549574 | AD15: 0.476884 | AE15: 0.602978 | AF15: 0.63303754 | AG15: 0.67060419 | AH15: 0.83081002 | AI15: 0.67656439
A16: 74 | B16: 110 | C16: topbetpeso | D16: 46063.513 | E16: 0 | F16: Apple Search Ads | G16: ASA | H16: 1 | I16: =VLOOKUP(A16,[1]模型分!$A:$T,20,FALSE) -> 556 | J16: 0.71652112 | K16: 0.54124831 | L16: 0.86797505 | M16: 0.67514977 | N16: 0.662404 | O16: 0.380424 | P16: 0.663369 | Q16: 0.318449 | R16: 0.495541 | S16: 548.31196
A17: 77 | B17: 116 | C17: topbetpeso | D17: 46063.644 | E17: 6 | F17: Apple Search Ads | G17: ASA | H17: 0 | I17: =VLOOKUP(A17,[1]模型分!$A:$T,20,FALSE) -> 0 | J17: 0.553777 | K17: 0.42270677 | L17: 0.899997 | M17: 0.79475316 | N17: 0.642268 | O17: 0.574802 | P17: 0.722646 | Q17: 0.499964 | R17: 0.548716 | S17: 499.35641
A18: 78 | B18: 115 | C18: oceanidfund | D18: 46110.296 | E18: 5 | F18: Apple Search Ads | G18: ASA | H18: 1 | I18: =VLOOKUP(A18,[1]模型分!$A:$T,20,FALSE) -> 0 | J18: -999 | K18: -999 | L18: 0.79470721 | M18: 0.67728385 | N18: 0.559112 | O18: 0.431389 | P18: 0.744909 | Q18: 0.499685 | R18: 0.408756 | S18: 507.90421 | T18: -1 | U18: -1 | V18: -1 | W18: -1 | X18: -1 | Y18: -1 | Z18: -1 | AA18: -1 | AB18: -1 | AC18: 0.431389 | AD18: 0.408756 | AE18: 0.559112 | AF18: -999 | AG18: -999 | AH18: 0.79470721 | AI18: 0.67728385
A19: 80 | B19: 117 | C19: oceanidfund | D19: 46110.323 | E19: 7 | F19: Apple Search Ads | G19: ASA | H19: 1 | I19: =VLOOKUP(A19,[1]模型分!$A:$T,20,FALSE) -> 710 | J19: 0.47735029 | K19: 0.35281238 | L19: 0.73549641 | M19: 0.67514977 | N19: 0.445654 | O19: 0.325453 | P19: 0.519088 | Q19: 0.432831 | R19: 0.32364 | S19: 597.84724 | T19: 702 | U19: 812 | V19: 721 | W19: 687 | X19: 563 | Y19: 596 | Z19: 579 | AA19: 721 | AB19: 756 | AC19: 0.325453 | AD19: 0.32364 | AE19: 0.445654 | AF19: 0.47735029 | AG19: 0.35281238 | AH19: 0.73549641 | AI19: 0.67514977
A20: 80 | B20: 123 | C20: topbetpeso | D20: 46063.877 | E20: 3 | F20: Apple Search Ads | G20: ASA | H20: 1 | I20: =VLOOKUP(A20,[1]模型分!$A:$T,20,FALSE) -> 710 | J20: 0.63641848 | K20: 0.5348972 | L20: 0.87900889 | M20: 0.70608932 | N20: 0.510471 | O20: 0.631999 | P20: 0.745119 | Q20: 0.551413 | R20: 0.500154 | S20: 499.62783
A21: 82 | B21: 117 | C21: topbetpeso | D21: 46063.944 | E21: 7 | F21: Apple Search Ads | G21: ASA | H21: 1 | I21: =VLOOKUP(A21,[1]模型分!$A:$T,20,FALSE) -> 427 | J21: 0.85954101 | K21: 0.83282634 | L21: 0.81510166 | M21: 0.70104258 | N21: 0.639595 | O21: 0.548853 | P21: 0.768356 | Q21: 0.47758 | R21: 0.54929 | S21: 549.54204
A22: 83 | B22: 122 | C22: oceanidfund | D22: 46110.36 | E22: 2 | F22: Apple Search Ads | G22: ASA | H22: 0 | I22: =VLOOKUP(A22,[1]模型分!$A:$T,20,FALSE) -> 0 | J22: 0.66477239 | K22: 0.81803209 | L22: 0.86943111 | M22: 0.67707045 | N22: 0.574326 | O22: 0.395429 | P22: 0.622519 | Q22: 0.425344 | R22: 0.482519 | S22: 548.8117 | T22: 429 | U22: 422 | V22: 418 | W22: 451 | X22: 397 | Y22: 432 | Z22: 427 | AA22: 487 | AB22: 484 | AC22: 0.395429 | AD22: 0.482519 | AE22: 0.574326 | AF22: 0.66477239 | AG22: 0.81803209 | AH22: 0.86943111 | AI22: 0.67707045
A23: 86 | B23: 128 | C23: oceanidfund | D23: 46110.399 | E23: 8 | F23: Apple Search Ads | G23: ASA | H23: 1 | I23: =VLOOKUP(A23,[1]模型分!$A:$T,20,FALSE) -> 0 | J23: -999 | K23: -999 | L23: 0.79936789 | M23: 0.67728385 | N23: 0.637072 | O23: 0.422589 | P23: 0.621682 | Q23: 0.489063 | R23: 0.479769 | S23: 517.56447 | T23: -1 | U23: -1 | V23: -1 | W23: -1 | X23: -1 | Y23: -1 | Z23: -1 | AA23: -1 | AB23: -1 | AC23: 0.422589 | AD23: 0.479769 | AE23: 0.637072 | AF23: -999 | AG23: -999 | AH23: 0.79936789 | AI23: 0.67728385
A24: 97 | B24: 146 | C24: oceanidfund | D24: 46110.484 | E24: 6 | F24: Apple Search Ads | G24: ASA | H24: 1 | I24: =VLOOKUP(A24,[1]模型分!$A:$T,20,FALSE) -> 0 | J24: -999 | K24: -999 | L24: 0.75607765 | M24: 0.67671704 | N24: 0.671867 | O24: 0.40601 | P24: 0.613398 | Q24: 0.489835 | R24: 0.523602 | S24: 528.01007 | T24: -1 | U24: -1 | V24: -1 | W24: -1 | X24: -1 | Y24: -1 | Z24: -1 | AA24: -1 | AB24: -1 | AC24: 0.40601 | AD24: 0.523602 | AE24: 0.671867 | AF24: -999 | AG24: -999 | AH24: 0.75607765 | AI24: 0.67671704
A25: 100 | B25: 147 | C25: oceanidfund | D25: 46110.489 | E25: 7 | F25: Apple Search Ads | G25: ASA | H25: 0 | I25: =VLOOKUP(A25,[1]模型分!$A:$T,20,FALSE) -> 895 | J25: 0.67337048 | K25: 0.68589919 | L25: 0.84563309 | M25: 0.67642279 | N25: 0.647337 | O25: 0.489971 | P25: 0.60362 | Q25: 0.44141 | R25: 0.472422 | S25: 538.03074 | T25: 457 | U25: 571 | V25: 560 | W25: 530 | X25: 513 | Y25: 530 | Z25: 516 | AA25: 617 | AB25: 617 | AC25: 0.489971 | AD25: 0.472422 | AE25: 0.647337 | AF25: 0.67337048 | AG25: 0.68589919 | AH25: 0.84563309 | AI25: 0.67642279
A26: 102 | B26: 149 | C26: oceanidfund | D26: 46110.5 | E26: 9 | F26: Apple Search Ads | G26: ASA | H26: 0 | I26: =VLOOKUP(A26,[1]模型分!$A:$T,20,FALSE) -> 638 | J26: 0.75461426 | K26: 0.71530209 | L26: 0.80250068 | M26: 0.67642279 | N26: 0.594969 | O26: 0.438984 | P26: 0.641853 | Q26: 0.494921 | R26: 0.550124 | S26: 488.10187 | T26: 446 | U26: 600 | V26: 573 | W26: 509 | X26: 377 | Y26: 426 | Z26: 392 | AA26: 456 | AB26: 421 | AC26: 0.438984 | AD26: 0.550124 | AE26: 0.594969 | AF26: 0.75461426 | AG26: 0.71530209 | AH26: 0.80250068 | AI26: 0.67642279
A27: 109 | B27: 160 | C27: oceanidfund | D27: 46110.554 | E27: 0 | F27: Apple Search Ads | G27: ASA | H27: 0 | I27: =VLOOKUP(A27,[1]模型分!$A:$T,20,FALSE) -> 723 | J27: 0.44699432 | K27: 0.21602163 | L27: 0.87370868 | M27: 0.67642279 | N27: 0.494667 | O27: 0.540884 | P27: 0.66843 | Q27: 0.44141 | R27: 0.400218 | S27: 555.02798 | T27: 670 | U27: 710 | V27: 666 | W27: 634 | X27: 575 | Y27: 635 | Z27: 570 | AA27: 712 | AB27: 740 | AC27: 0.540884 | AD27: 0.400218 | AE27: 0.494667 | AF27: 0.44699432 | AG27: 0.21602163 | AH27: 0.87370868 | AI27: 0.67642279
A28: 113 | B28: 163 | C28: oceanidfund | D28: 46110.57 | E28: 3 | F28: Apple Search Ads | G28: ASA | H28: 0 | I28: =VLOOKUP(A28,[1]模型分!$A:$T,20,FALSE) -> 660 | J28: 0.1905754 | K28: 0.21889625 | L28: 0.80044382 | M28: 0.67728385 | N28: 0.701897 | O28: 0.590545 | P28: 0.686922 | Q28: 0.555442 | R28: 0.561703 | S28: 498.1903 | T28: 673 | U28: 559 | V28: 621 | W28: 615 | X28: 557 | Y28: 605 | Z28: 578 | AA28: 670 | AB28: 698 | AC28: 0.590545 | AD28: 0.561703 | AE28: 0.701897 | AF28: 0.1905754 | AG28: 0.21889625 | AH28: 0.80044382 | AI28: 0.67728385
A29: 119 | B29: 171 | C29: topbetpeso | D29: 46064.331 | E29: 1 | F29: Apple Search Ads | G29: ASA | H29: 1 | I29: =VLOOKUP(A29,[1]模型分!$A:$T,20,FALSE) -> 566 | J29: 0.78674745 | K29: 0.70559745 | L29: 0.92244771 | M29: 0.67671704 | N29: 0.532635 | O29: 0.49086 | P29: 0.678117 | Q29: 0.478713 | R29: 0.554121 | S29: 504.85372
A30: 122 | B30: 170 | C30: topbetpeso | D30: 46064.337 | E30: 0 | F30: Apple Search Ads | G30: ASA | H30: 1 | I30: =VLOOKUP(A30,[1]模型分!$A:$T,20,FALSE) -> 579 | J30: 0.58217164 | K30: 0.58860033 | L30: 0.89079108 | M30: 0.67604285 | N30: 0.529322 | O30: 0.41701 | P30: 0.639638 | Q30: 0.3941 | R30: 0.366651 | S30: 517.95142
A31: 124 | B31: 177 | C31: oceanidfund | D31: 46110.688 | E31: 7 | F31: Apple Search Ads | G31: ASA | H31: 0 | I31: =VLOOKUP(A31,[1]模型分!$A:$T,20,FALSE) -> 768 | J31: 0.62107567 | K31: 0.50302193 | L31: 0.76049614 | M31: 0.67671704 | N31: 0.63892 | O31: 0.453218 | P31: 0.733911 | Q31: 0.551905 | R31: 0.562103 | S31: 510.44508 | T31: 432 | U31: 599 | V31: 625 | W31: 468 | X31: 444 | Y31: 518 | Z31: 414 | AA31: 463 | AB31: 499 | AC31: 0.453218 | AD31: 0.562103 | AE31: 0.63892 | AF31: 0.62107567 | AG31: 0.50302193 | AH31: 0.76049614 | AI31: 0.67671704
A32: 128 | B32: 179 | C32: topbetpeso | D32: 46064.357 | E32: 9 | F32: Apple Search Ads | G32: ASA | H32: 1 | I32: =VLOOKUP(A32,[1]模型分!$A:$T,20,FALSE) -> 0 | J32: 0.5850145 | K32: 0.64099192 | L32: 0.88400607 | M32: 0.67656439 | N32: 0.610738 | O32: 0.434569 | P32: 0.588756 | Q32: 0.34084 | R32: 0.525399 | S32: 553.89244
A33: 132 | B33: 187 | C33: oceanidfund | D33: 46110.775 | E33: 7 | F33: Apple Search Ads | G33: ASA | H33: 0 | I33: =VLOOKUP(A33,[1]模型分!$A:$T,20,FALSE) -> 660 | J33: 0.67115989 | K33: 0.56497548 | L33: 0.81584408 | M33: 0.67537235 | N33: 0.596322 | O33: 0.54499 | P33: 0.778694 | Q33: 0.537991 | R33: 0.43458 | S33: 543.69603 | T33: 632 | U33: 529 | V33: 604 | W33: 593 | X33: 567 | Y33: 604 | Z33: 532 | AA33: 608 | AB33: 649 | AC33: 0.54499 | AD33: 0.43458 | AE33: 0.596322 | AF33: 0.67115989 | AG33: 0.56497548 | AH33: 0.81584408 | AI33: 0.67537235
A34: 142 | B34: 204 | C34: oceanidfund | D34: 46110.91 | E34: 4 | F34: Apple Search Ads | G34: ASA | H34: 1 | I34: =VLOOKUP(A34,[1]模型分!$A:$T,20,FALSE) -> 741 | J34: 0.3122118 | K34: 0.26856713 | L34: 0.85588524 | M34: 0.67514977 | N34: 0.627377 | O34: 0.350566 | P34: 0.654635 | Q34: 0.544457 | R34: 0.463947 | S34: 513.91022 | T34: 658 | U34: 577 | V34: 624 | W34: 615 | X34: 504 | Y34: 643 | Z34: 570 | AA34: 666 | AB34: 676 | AC34: 0.350566 | AD34: 0.463947 | AE34: 0.627377 | AF34: 0.3122118 | AG34: 0.26856713 | AH34: 0.85588524 | AI34: 0.67514977
A35: 146 | B35: 215 | C35: oceanidfund | D35: 46111.064 | E35: 5 | F35: Apple Search Ads | G35: ASA | H35: 1 | I35: =VLOOKUP(A35,[1]模型分!$A:$T,20,FALSE) -> 555 | J35: 0.41421152 | K35: 0.36999388 | L35: 0.78544614 | M35: 0.67656439 | N35: 0.517462 | O35: 0.461693 | P35: 0.691105 | Q35: 0.495861 | R35: 0.416708 | S35: 519.36539 | T35: 644 | U35: 548 | V35: 607 | W35: 600 | X35: 526 | Y35: 547 | Z35: 566 | AA35: 629 | AB35: 619 | AC35: 0.461693 | AD35: 0.416708 | AE35: 0.517462 | AF35: 0.41421152 | AG35: 0.36999388 | AH35: 0.78544614 | AI35: 0.67656439
A36: 153 | B36: 226 | C36: oceanidfund | D36: 46111.198 | E36: 6 | F36: Apple Search Ads | G36: ASA | H36: 0 | I36: =VLOOKUP(A36,[1]模型分!$A:$T,20,FALSE) -> 876 | J36: 0.46701893 | K36: 0.29781338 | L36: 0.84222126 | M36: 0.67642279 | N36: 0.506259 | O36: 0.525764 | P36: 0.687676 | Q36: 0.522819 | R36: 0.340748 | S36: 560.41012 | T36: 499 | U36: 728 | V36: 660 | W36: 569 | X36: 591 | Y36: 650 | Z36: 565 | AA36: 678 | AB36: 678 | AC36: 0.525764 | AD36: 0.340748 | AE36: 0.506259 | AF36: 0.46701893 | AG36: 0.29781338 | AH36: 0.84222126 | AI36: 0.67642279
A37: 155 | B37: 220 | C37: topbetpeso | D37: 46064.367 | E37: 0 | F37: Apple Search Ads | G37: ASA | H37: 1 | I37: =VLOOKUP(A37,[1]模型分!$A:$T,20,FALSE) -> 582 | J37: 0.5587405 | K37: 0.40502944 | L37: 0.86616627 | M37: 0.67728385 | N37: 0.579191 | O37: 0.365622 | P37: 0.708232 | Q37: 0.451569 | R37: 0.459685 | S37: 525.87856
A38: 159 | B38: 234 | C38: oceanidfund | D38: 46111.268 | E38: 4 | F38: Apple Search Ads | G38: ASA | H38: 1 | I38: =VLOOKUP(A38,[1]模型分!$A:$T,20,FALSE) -> 694 | J38: -999 | K38: -999 | L38: 0.76987973 | M38: 0.67671704 | N38: 0.56898 | O38: 0.4503 | P38: 0.648569 | Q38: 0.441743 | R38: 0.403647 | S38: 572.14513 | T38: -1 | U38: -1 | V38: -1 | W38: -1 | X38: -1 | Y38: -1 | Z38: -1 | AA38: -1 | AB38: -1 | AC38: 0.4503 | AD38: 0.403647 | AE38: 0.56898 | AF38: -999 | AG38: -999 | AH38: 0.76987973 | AI38: 0.67671704
A39: 160 | B39: 169 | C39: oceanidfund | D39: 46111.27 | E39: 9 | F39: Apple Search Ads | G39: ASA | H39: 1 | I39: =VLOOKUP(A39,[1]模型分!$A:$T,20,FALSE) -> 769 | J39: 0.41071699 | K39: 0.31886065 | L39: 0.80685707 | M39: 0.67656439 | N39: 0.583965 | O39: 0.449177 | P39: 0.649023 | Q39: 0.513402 | R39: 0.535209 | S39: 574.0768 | T39: 677 | U39: 634 | V39: 623 | W39: 620 | X39: 586 | Y39: 560 | Z39: 583 | AA39: 664 | AB39: 662 | AC39: 0.449177 | AD39: 0.535209 | AE39: 0.583965 | AF39: 0.41071699 | AG39: 0.31886065 | AH39: 0.80685707 | AI39: 0.67656439
A40: 161 | B40: 219 | C40: topbetpeso | D40: 46064.37 | E40: 9 | F40: Apple Search Ads | G40: ASA | H40: 1 | I40: =VLOOKUP(A40,[1]模型分!$A:$T,20,FALSE) -> 694 | J40: 0.82618441 | K40: 0.81762675 | L40: 0.77522844 | M40: 0.79186649 | N40: 0.591148 | O40: 0.444931 | P40: 0.597384 | Q40: 0.336376 | R40: 0.457272 | S40: 503.45017
...
